{"tests": [{"name": "Base case (provided by the question)", "max_points": 1, "filename": "test_0", "points": 0, "files": [], "message": "The callable 'same_values' supplied in your code failed with an exception while it was being called by the grading code:Traceback (most recent call last):\n  File \"/grade/run/code_feedback.py\", line 408, in call_user\n    return f(*args, **kwargs)\n  File \"<string>\", line 3, in same_values\nNameError: name 'GP' is not defined\n\n"}], "score": 0.0, "succeeded": true, "gradable": true, "max_points": 10, "images": []}