{"tests": [{"name": "Check nib(0)", "max_points": 0.5, "filename": "test_0", "points": 0.5, "files": [], "message": "'nib(0)' looks good\n"}, {"name": "Check nib(1)", "max_points": 0.5, "filename": "test_1", "points": 0.5, "files": [], "message": "'nib(1)' looks good\n"}, {"name": "Check nib(7)", "max_points": 1, "filename": "test_2", "points": 0, "files": [], "message": "The callable 'nib' supplied in your code failed with an exception while it was being called by the grading code:Traceback (most recent call last):\n  File \"/grade/run/code_feedback.py\", line 408, in call_user\n    return f(*args, **kwargs)\n  File \"<string>\", line 2, in nib\nIndexError: list index out of range\n\n"}], "score": 0.1, "succeeded": true, "gradable": true, "max_points": 10.0, "images": []}