{"tests": [{"name": "Internal Grading Error", "filename": "error", "max_points": 1, "points": 0, "files": [], "message": "The grading code was not able to run.\nPlease notify the course staff and include this entire message,\nincluding the traceback below.\n\nThe error traceback is:\nTraceback (most recent call last):\n  File \"/usr/lib64/python3.6/unittest/suite.py\", line 163, in _handleClassSetUp\n    setUpClass()\n  File \"/grade/run/pl_unit_test.py\", line 44, in setUpClass\n    self.data = json.load(f)\n  File \"/usr/lib64/python3.6/json/__init__.py\", line 296, in load\n    return loads(fp.read(),\n  File \"/usr/lib64/python3.6/encodings/ascii.py\", line 26, in decode\n    return codecs.ascii_decode(input, self.errors)[0]\nUnicodeDecodeError: 'ascii' codec can't decode byte 0xe2 in position 178: ordinal not in range(128)\n\n"}], "score": 0.0, "succeeded": true, "gradable": false, "max_points": 1, "images": []}